Workbook

Sheet ELE
A1: AREA | B1: EQUIPMENT | C1: ELECTRICAL CONSUPTION | J1: ELE. REAL
C2: KW | D2: KVA | E2: QTY | F2: TOTAL (KVA) | H2: % Potencia | I2: % Tiempo | J2: % Utilización | K2: TOTAL (KVA)
A3: LASER | B3: METAL LASER 3000W GENERATOR + CHILLER | C3: =+cirotec2024!D19 -> 23 | D3: =+C3*1.25 -> 28.75 | E3: 4 | F3: =+D3*E3 -> 115 | H3: 0.33 | I3: 0.6 | J3: =+H3*I3 -> 0.198 | K3: =+J3*F3 -> 22.77
B4: CHILLER FOR LASER | C4: =+cirotec2024!D11 -> 5.0 | D4: =+C4*1.25 -> 6.25 | E4: 4 | F4: =+D4*E4 -> 25 | H4: 0.5 | I4: 0.5 | J4: =+H4*I4 -> 0.25 | K4: =+J4*F4 -> 6.25
B5: ELECTRICAL SPIKE SUPPRESSOR REGULATOR MODEL TOUCH 220VAC 100A | C5: 0 | D5: =+C5*1.25 -> 0 | E5: 4 | F5: =+D5*E5 -> 0 | H5: 0 | I5: 0 | J5: =+H5*I5 -> 0 | K5: =+J5*F5 -> 0
B6: THREE-PHASE ELECTRIC POWER TRANSFORMER 60KVA-3F-220-380 | C6: =+M6 -> 0 | D6: =+C6*1.25 -> 0 | E6: 4 | F6: =+D6*E6 -> 0 | H6: 0 | I6: 0 | J6: =+H6*I6 -> 0 | K6: =+J6*F6 -> 0
B7: COMPRESSOR MODEL: BOSS DREI BCT-3022-SET SCREW COMPRESSOR, 30 HP/22 KW | C7: =+cirotec2024!D14 -> 22 | D7: =+C7*1.25 -> 27.5 | E7: 4 | F7: =+D7*E7 -> 110 | H7: 0.6 | I7: 0.3 | J7: =+H7*I7 -> 0.18 | K7: =+J7*F7 -> 19.8
B8: DUST COLLECTOR FOR LASER CUTTING MACHINES | C8: =+M8 -> 0 | D8: =+C8*1.25 -> 0 | E8: 4 | F8: =+D8*E8 -> 0 | H8: 0 | I8: 0 | J8: =+H8*I8 -> 0 | K8: =+J8*F8 -> 0
B9: Sub-Total | F9: =SUM(F3:F8) -> 250 | J9: =+H9*I9 -> 0 | K9: =SUM(K3:K8) -> 48.82
A10: BENDING | B10: BENDING MACHINE 200-TON WITH NC, 3.2 METERS INCLUDED ACCESSORIES 3 AXES + TOUCH PANEL (TP10S TOUCH) | C10: =+cirotec2024!D24*1.5 -> 11.25 | D10: =+C10*1.25 -> 14.0625 | E10: 1 | F10: =+D10*E10 -> 14.0625 | H10: 0.9 | I10: 0.8 | J10: =+H10*I10 -> 0.72 | K10: =+J10*F10 -> 10.125
B11: SUPRESOR DE SOBRETENSIONES TRANSISTORIAS | C11: 0 | D11: =+C11*1.25 -> 0 | E11: 1 | F11: =+D11*E11 -> 0 | J11: =+H11*I11 -> 0 | K11: =+J11*F11 -> 0
B12: ADDITIONAL CONTROL E300 | C12: 0 | D12: =+C12*1.25 -> 0 | E12: 1 | F12: =+D12*E12 -> 0 | J12: =+H12*I12 -> 0 | K12: =+J12*F12 -> 0
B13: BENDING MACHINE 63-TON, NC, 1.6 METERS, AND ACCESSORIES INCLUDED. 3-AXIS + TOUCH PANEL (TP10S TOUCH) | C13: =+cirotec2024!D23 -> 5.5 | D13: =+C13*1.25 -> 6.875 | E13: 1 | F13: =+D13*E13 -> 6.875 | H13: 1 | I13: 0.8 | J13: =+H13*I13 -> 0.8 | K13: =+J13*F13 -> 5.5
B14: STAMPING PRESS 40 TON | C14: 3 | D14: =+C14*1.25 -> 3.75 | E14: 1 | F14: =+D14*E14 -> 3.75 | H14: 1 | I14: 0.8 | J14: =+H14*I14 -> 0.8 | K14: =+J14*F14 -> 3
B15: SUPRESOR DE SOBRETENSIONES TRANSISTORIAS | C15: 0 | D15: =+C15*1.25 -> 0 | E15: 1 | F15: =+D15*E15 -> 0 | J15: =+H15*I15 -> 0 | K15: =+J15*F15 -> 0
B16: Sub-Total | F16: =SUM(F10:F15) -> 24.6875 | J16: =+H16*I16 -> 0 | K16: =SUM(K10:K15) -> 18.625
A17: DEBURING | B17: DEBURING MACHINE BIG SIZE XRB SAND-P1300 | C17: 54 | D17: =+C17*1.25 -> 67.5 | E17: 1 | F17: =C17*E17 -> 54 | H17: 0.35 | I17: 0.8 | J17: =+H17*I17 -> 0.28 | K17: =+J17*F17 -> 15.12
B18: DEBURING MACHINE SMALL SIZE XRB Open Table SAND-R330 | C18: 7.5 | D18: =+C18*1.25 -> 9.375 | E18: 1 | F18: =C18*E18 -> 7.5 | H18: 0.35 | I18: 0.8 | J18: =+H18*I18 -> 0.28 | K18: =+J18*F18 -> 2.1
B19: WATER SandBlasting SAND-U520 de 200L | C19: 0 | D19: =+C19*1.25 -> 0 | E19: 1 | F19: =C19*E19 -> 0 | J19: =+H19*I19 -> 0 | K19: =+J19*F19 -> 0
B20: TABLES & TOOLS FOR GRINDING | C20: 0 | D20: =+C20*1.25 -> 0 | E20: 1 | F20: =+E20*C20 -> 0 | J20: =+H20*I20 -> 0 | K20: =+J20*F20 -> 0
D21: =+C21*1.25 -> 0 | J21: =+H21*I21 -> 0 | K21: =+J21*F21 -> 0
B22: Sub-Total | F22: =SUM(F17:F21) -> 61.5 | J22: =+H22*I22 -> 0 | K22: =SUM(K17:K21) -> 17.22
A23: COATING | B23: ELECTROSTATIC PAINTING CABINET, AREA 3.90 X 2.40 MTS | C23: 5 | D23: =+C23*1.25 -> 6.25 | E23: 1 | F23: =+D23*E23 -> 6.25 | H23: 1 | I23: 1 | J23: =+H23*I23 -> 1 | K23: =+J23*F23 -> 6.25
B24: OVEN: POWDER COATING OVEN, 4000 X 3000 MM AREA, 380V ELECTROSTATIC | C24: 10 | D24: =+C24*1.25 -> 12.5 | E24: 1 | F24: =+D24*E24 -> 12.5 | H24: 1 | I24: 1 | J24: =+H24*I24 -> 1 | K24: =+J24*F24 -> 12.5
B25: SPRAY GUN AND MACHINE FOR PAINT APPLICATION, ELECTROSTATIC AREA FEM1910S FULL SET | C25: 1 | D25: =+C25*1.25 -> 1.25 | E25: 1 | F25: =+D25*E25 -> 1.25 | H25: 1 | I25: 1 | J25: =+H25*I25 -> 1 | K25: =+J25*F25 -> 1.25
D26: =+C26*1.25 -> 0 | F26: =+D26*E26 -> 0 | J26: =+H26*I26 -> 0 | K26: =+J26*F26 -> 0
D27: =+C27*1.25 -> 0 | F27: =+D27*E27 -> 0 | J27: =+H27*I27 -> 0 | K27: =+J27*F27 -> 0
B28: Sub-Total | F28: =SUM(F23:F27) -> 20 | J28: =+H28*I28 -> 0 | K28: =SUM(K23:K27) -> 20
A29: WELDING | B29: LASER WELDER: 2000-W CAPACITY, 3-IN-1 MULTIFUNCTION WITH AUTOMATIC FEEDER AND ACCESSORY SET. VOLTAGE REGULATOR INCLUDED. | C29: 2 | D29: =+C29*1.25 -> 2.5 | E29: 1 | F29: =+D29*E29 -> 2.5 | H29: 0.8 | I29: 0.5 | J29: =+H29*I29 -> 0.4 | K29: =+J29*F29 -> 1
B30: THREE-PHASE ELECTRIC POWER TRANSFORMER 50KVA-3F-220-380 | C30: 0 | D30: =+C30*1.25 -> 0 | E30: 1 | F30: =+D30*E30 -> 0 | J30: =+H30*I30 -> 0 | K30: =+J30*F30 -> 0
B31: Sub-Total | F31: =SUM(F29:F30) -> 2.5 | J31: =+H31*I31 -> 0 | K31: =SUM(K29:K30) -> 1
A32: TOOLING | B32: BENDING TOOLINGE SET | C32: 0 | D32: =+C32*1.25 -> 0 | E32: 1 | F32: =+D32*E32 -> 0 | J32: =+H32*I32 -> 0 | K32: =+J32*F32 -> 0
B33: PRODUCTION CARS FOR TOOLING | C33: 0 | D33: =+C33*1.25 -> 0 | E33: 2 | F33: =+D33*E33 -> 0 | J33: =+H33*I33 -> 0 | K33: =+J33*F33 -> 0
B34: PAINT HANGERS & CARRIERS | C34: 0 | D34: =+C34*1.25 -> 0 | E34: 1 | F34: =+D34*E34 -> 0 | J34: =+H34*I34 -> 0 | K34: =+J34*F34 -> 0
B35: PRESS MACHINE 65T | C35: 10 | D35: =+C35*1.25 -> 12.5 | E35: 1 | F35: =+D35*E35 -> 12.5 | H35: 1 | I35: 0.8 | J35: =+H35*I35 -> 0.8 | K35: =+J35*F35 -> 10
B36: TOOLING MFG LOCAL | C36: 0 | D36: =+C36*1.25 -> 0 | E36: 1 | F36: =+D36*E36 -> 0 | J36: =+H36*I36 -> 0 | K36: =+J36*F36 -> 0
B37: Sub-Total | F37: =SUM(F32:F36) -> 12.5 | J37: =+H37*I37 -> 0 | K37: =SUM(K32:K36) -> 10
A38: ERECTION | B38: FACILITIES INSTALLATION | C38: 0 | D38: =+C38*1.25 -> 0 | E38: 1 | F38: =+D38*E38 -> 0 | J38: =+H38*I38 -> 0 | K38: =+G38*J38 -> 0
B39: SUB-ESTACION 250 - 300 KVA | C39: 0 | D39: =+C39*1.25 -> 0 | E39: 1 | F39: =+D39*E39 -> 0 | J39: =+H39*I39 -> 0 | K39: =+G39*J39 -> 0
B40: ELECTRICAL FEEDERS | C40: 0 | D40: =+C40*1.25 -> 0 | E40: 1 | F40: =+D40*E40 -> 0 | J40: =+H40*I40 -> 0 | K40: =+G40*J40 -> 0
...

Sheet COMPRESOR

Sheet Deburring
B2: 7.5 | C2: 2 | D2: =+C2*B2 -> 15
B3: 5.5 | C3: 1 | D3: =+C3*B3 -> 5.5
B4: 1.5 | C4: 1 | D4: =+C4*B4 -> 1.5
D5: =SUM(D2:D4) -> 22

Sheet cirotec2024
A1: No. | B1: Descripción detallada ó de catálogo | C1: Area | D1: Potencia (KW) | E1: Potencia (HP) | F1: Voltaje (V) | G1: Corriente (A) | H1: Verificación (A) | I1: Phases (#) | J1: Tierra (Ohms) | K1: Neutro
A2: 1 | B2: Maquina de soldar (Soldadura electrodo) lincon electric | C2: Weld | D2: 24.2 | E2: 32.45 | F2: 220/440 | G2: 110/55 | I2: 3
A3: 2 | B3: Máquina para soldar con microalambre | C3: Weld | D3: 10.5 | E3: 14.08 | F3: 220 | G3: 48 | I3: 2
A4: 3 | B4: Maquina de soldar Fronius | C4: Weld | D4: 13.86 | E4: 18.6 | F4: 220/440 | G4: 63/35 | I4: 3
A5: 4 | B5: Soldadura Argón Miller | C5: Weld | D5: 6.6 | E5: 8.8 | F5: 220 | G5: 30 | I5: 2
A6: 5 | B6: Punteadora mecanica | C6: Weld | D6: 20 | E6: 26.8 | F6: 220 | G6: 70 | H6: 72 | I6: 2
A7: 6 | B7: Cortadora de metales urrea | C7: Weld | D7: 3 | E7: 4 | F7: 220 | G7: 13.64 | H7: 10.2 | I7: 3
A8: 7 | B8: Cortadora makita | C8: Weld | D8: 1.73 | E8: 2.31 | F8: 115 | G8: 15 | H8: 13.1 | I8: 1
A9: 8 | B9: Compresor de aire presión 175 Llb/plg | C9: Weld | D9: 3.7 | E9: 4.9 | F9: 220 v | G9: 12.5 | H9: 11.5 | I9: 3
A10: 10 | B10: Lasér CNC de fibra Óptica X0 | C10: Steel | D10: 12 | E10: 30.8 | F10: 220 | G10: 60.6 | H10: 14.1 | I10: 3 | J10: SI
A11: 11 | B11: Chiller | C11: Steel | D11: 5.0 | E11: 6.7 | F11: 220 | G11: 21.5 | H11: 24 | I11: 2
A12: 12 | B12: Lasér CNC de fibra Óptica X3 | C12: Steel | D12: 14.4 | E12: 19.3 | F12: 380 | G12: 38 | H12: 21.4 | I12: 3
A13: 13 | B13: Chiller X3 | C13: Steel | D13: 5.06 | E13: 6.7 | F13: 380 | G13: 13.3 | H13: 6.7 | I13: 3
A14: 14 | B14: Compresor BCT-3020-Set | C14: Steel | D14: 22 | E14: 29.49 | F14: 380 | G14: 28 | H14: 34 | I14: 3 | K14: 127
A15: 14.1 | B15: Secador de compresor BCT-3020-Set | C15: Steel | D15: 0.765 | E15: 0.001 | F15: 220 | G15: 3.3 | H15: 3.3 | I15: 2 | J15: SI
A16: 15 | B16: Compresor BC-T2015 | C16: Steel | D16: 15 | E16: 20.1 | F16: 220 | G16: 68.2 | H16: 34 | I16: 3
A17: 16 | B17: Compresor de aire presión 175 Llb/plg | C17: Steel | D17: 3.7 | E17: 4.9 | F17: 220 v | G17: 12.5 | H17: 11.3 | I17: 3
A18: 17 | B18: Compresor I 800 | C18: Steel | D18: 7.46 | E18: 10 | F18: 220 | G18: 24.8 | H18: 21.2 | I18: 3 | J18: SI
A19: 19 | B19: Lasér CNC de fibra Óptica Jet 3015 | C19: Steel | D19: 23 | E19: 30.8 | F19: 380 | G19: 60.6 | H19: 12.2 | I19: 3 | J19: SI
A20: 20 | B20: Chiller para Jet 3015 | C20: Steel | D20: 5 | E20: 6.7 | F20: 220 | G20: 16.8 | H20: 15.7 | I20: 2 | J20: SI
A21: 21 | B21: Lasér CNC de fibra Óptica FC315A | C21: Steel | D21: 23 | E21: 30.8 | F21: 380 | G21: 60.6 | H21: 13 | I21: 3
A22: 22 | B22: Chiller para FC315A | C22: Steel | D22: 5.5 | E22: 6.7 | F22: 380 | G22: 13.4 | H22: 11.9 | I22: 3 | J22: SI
A23: 23 | B23: Dobladora FlexCNC 63 TON | C23: Doblado | D23: 5.5 | E23: 7.3 | F23: 220 | G23: 20.5 | H23: 10.1 | I23: 3 | K23: 124.2
A24: 24 | B24: Dobladora FlexCNC 125 TON | C24: Doblado | D24: 7.5 | E24: 10 | F24: 220 | G24: 27 | H24: 11.7 | I24: 3 | K24: 124.2
A25: 25 | B25: Prensa | C25: Doblado | D25: 3.730 | E25: 5 | F25: 230 | G25: 13 | H25: 21 | I25: 3 | K25: 124.2
A26: 26 | B26: Troqueladora Convencional | C26: Doblado | D26: 2.2 | E26: 2.9 | F26: 220 | G26: 20 | H26: 6.9 | I26: 3
A27: 27 | B27: Sierra cinta Vertical | C27: Maquinado | D27: 1.5 | E27: 2 HP | F27: 220 | G27: 6.78 | H27: 3.1 | I27: 3
A28: 28 | B28: Sierra cinta horizontal | C28: Maquinado | D28: 2.2 | E28: 2.9 | F28: 220 | G28: 8.22 | H28: 5.7 | I28: 3
A29: 29 | B29: Compresor de aire presión 175 Llb/plg | C29: Maquinado | D29: 3.7 | E29: 4.9 | F29: 220 v | G29: 12.5 | H29: 19 | I29: 3
A30: 30 | B30: Afiladora | C30: Maquinado | D30: 0.18 | E30: 0.2 | F30: 220 | G30: 0.8 | H30: 0.8 | I30: 3
A31: 31 | B31: Router CNC | C31: Maquinado | D31: 8.5 | E31: 6 | F31: 220 | G31: 43 | I31: 2
A32: 32 | B32: Centro de maquinado CNC | C32: Maquinado | D32: 9.6 | E32: 12.8 | F32: 220 | G32: 30 | H32: 8.7 | I32: 3
A33: 33 | B33: Fresadora lector digital (MH-01-FLD02) | C33: Maquinado | D33: 2.24 | E33: 3 | F33: 220 | G33: 10.17 | H33: 5.7 | I33: 3 | K33: 0
A34: 34 | B34: Fresadora lector digital (MH-01-FLD03) | C34: Maquinado | D34: 2.24 | E34: 3 | F34: 220 | G34: 10.7 | H34: 3.7 | I34: 3
A35: 35 | B35: Fresadora lector digital (MH-01-FLD01 | C35: Maquinado | D35: 2.24 | E35: 3 | F35: 220 | G35: 10.7 | H35: 4.2 | I35: 3
A36: 36 | B36: Fresadora lector digital (MH-01-FLD04) | C36: Maquinado | D36: 2.24 | E36: 3 | F36: 220 | G36: 10.7 | H36: 5.6 | I36: 3
A37: 37 | B37: Fresadora CNC (MH-01-FCNC02) | C37: Maquinado | D37: 3.7 | E37: 5 | F37: 220 | G37: 15 | H37: 5.6 | I37: 3 | K37: 127.1
A38: 38 | B38: Fresadora CNC (MH-01-FCNC03) | C38: Maquinado | D38: 3.7 | E38: 5 | F38: 220 | G38: 14.3 | H38: 3.8 | I38: 3 | K38: 127.2
A39: 39 | B39: Torno CNC | C39: Maquinado | D39: 15 | E39: 20.1 | F39: 220 | G39: 41 | H39: 7.2 | I39: 3 | J39: SI
A40: 40 | B40: Rectificadora de superficies planas | C40: Maquinado | D40: 6.4 | E40: 8.5 | F40: 220 | G40: 40 | H40: 10 | I40: 3 | K40: 127.1
...
